<?xml version="1.0" encoding="utf-8"?>
<!-- This URDF was automatically created by SolidWorks to URDF Exporter! Originally created by Stephen Brawner (brawner@gmail.com) 
     Commit Version: 1.6.0-1-g15f4949  Build Version: 1.6.7594.29634
     For more information, please see http://wiki.ros.org/sw_urdf_exporter
     
     Generated by SW2URDF. Then manually added Gazebo transmissions. - Josh Davy
      -->


<robot
  name="thorvald_arm">

  <gazebo>
    <plugin name="gazebo_ros_control" filename="libgazebo_ros_control.so">
    <robotNamespace>thorvald_arm</robotNamespace>
    </plugin>
  </gazebo>



  <!-- <link name="/world"/>

  <joint name="fixed" type="fixed">
    <parent link="world"/>
    <child link="base_link"/>
    <origin
      xyz="0 0 1"
      rpy="1.5708 0 0" />
  </joint> -->


  <link name="/thorvald_001/base_link"/>
  <joint name="arm_to_thorvald" type="fixed">
    <parent link="/thorvald_001/base_link"/>
    <child link="base_link"/>
    <origin
      xyz="0 0 3"
      rpy="1.5708 0 0" />
  </joint>


  <link name="base_link">
    <inertial>
      <origin
        xyz="0 0.026015 0"
        rpy="0 0 0" />
      <mass
        value="1.3548" />
      <inertia
        ixx="0.0012241"
        ixy="0"
        ixz="0"
        iyy="0.010139"
        iyz="0"
        izz="0.0094931" />
    </inertial>
    <visual>
      <origin
        xyz="0 0 0"
        rpy="0 0 0" />
      <geometry>
        <mesh
          filename="package://thorvald_arm/meshes/base_link.STL" />
      </geometry>
      <material
        name="">
        <color
          rgba="0.79216 0.81961 0.93333 1" />
      </material>
    </visual>
    <collision>
      <origin
        xyz="0 0 0"
        rpy="0 0 0" />
      <geometry>
        <mesh
          filename="package://thorvald_arm/meshes/base_link.STL" />
      </geometry>
    </collision>
  </link>

  <link name="link1">
    <inertial>
      <origin
        xyz="0.16 0.095 0"
        rpy="0 0 0" />
      <mass
        value="0.65" />
      <inertia
        ixx="0.00011077"
        ixy="0"
        ixz="0"
        iyy="0.0090954"
        iyz="0"
        izz="0.0090393" />
    </inertial>
    <visual>
      <origin
        xyz="0 0 0"
        rpy="0 0 0" />
      <geometry>
        <mesh
          filename="package://thorvald_arm/meshes/link1.STL" />
      </geometry>
      <material
        name="">
        <color
          rgba="0.89804 0.91765 0.92941 1" />
      </material>
    </visual>
    <collision>
      <origin
        xyz="0 0 0"
        rpy="0 0 0" />
      <geometry>
        <mesh
          filename="package://thorvald_arm/meshes/link1.STL" />
      </geometry>
    </collision>
  </link>

  <joint name="joint1"
    type="continuous">
    <origin
      xyz="0 0 0"
      rpy="1.5708 0 0" />
    <parent
      link="base_link" />
    <child
      link="link1" />
    <axis
      xyz="0 1 0" />

    <dynamics damping="1.5"/>
    <limit effort="30" velocity="1.0" />
  </joint>

  <link name="link2">
    <inertial>
      <origin
        xyz="-0.16 -0.025 0"
        rpy="0 0 0" />
      <mass
        value="0.65" />
      <inertia
        ixx="0.00011077"
        ixy="0"
        ixz="0"
        iyy="0.0090954"
        iyz="0"
        izz="0.0090393" />
    </inertial>
    <visual>
      <origin
        xyz="0 0 0"
        rpy="0 0 0" />
      <geometry>
        <mesh
          filename="package://thorvald_arm/meshes/link2.STL" />
      </geometry>
      <material
        name="">
        <color
          rgba="0.89804 0.91765 0.92941 1" />
      </material>
    </visual>
    <collision>
      <origin
        xyz="0 0 0"
        rpy="0 0 0" />
      <geometry>
        <mesh
          filename="package://thorvald_arm/meshes/link2.STL" />
      </geometry>
    </collision>
  </link>

  <joint name="joint2"
    type="continuous">
    <origin
      xyz="0.32 0.12 0"
      rpy="0 0 3.14159265358979" />
    <parent
      link="link1" />
    <child
      link="link2" />
    <axis
      xyz="0 1 0" />
    <dynamics damping="0.7"/>
    <limit effort="30" velocity="1.0" />
  </joint>

  <link name="nozzle">
    <inertial>
      <origin
        xyz="0 -0.004541 0.026567"
        rpy="0 0 0" />
      <mass
        value="0.1" />
      <inertia
        ixx="0.0001"
        ixy="0"
        ixz="0"
        iyy="0.005"
        iyz="0"
        izz="0.01" />
    </inertial>
    <visual>
      <origin
        xyz="0 0 0"
        rpy="0 0 0" />
      <geometry>
        <mesh
          filename="package://thorvald_arm/meshes/nozzle.STL" />
      </geometry>
      <material
        name="">
        <color
          rgba="0.79216 0.81961 0.93333 1" />
      </material>
    </visual>
    <collision>
      <origin
        xyz="0 0 0"
        rpy="0 0 0" />
      <geometry>
        <mesh
          filename="package://thorvald_arm/meshes/nozzle.STL" />
      </geometry>
    </collision>
  </link>

  <joint name="nozzle_joint"
    type="continuous">
    <origin
      xyz="-0.32 -0.05 0"
      rpy="-1.5707963267949 0 3.14159265358979" />
    <parent
      link="link2" />
    <child
      link="nozzle" />
    <axis
      xyz="0 0 1" />
    <dynamics damping="0.7"/>
    <limit effort="30" velocity="1.0"/>
  </joint>

  <!-- Transmissions -->
 
  <transmission name="tran1">
    <type>transmission_interface/SimpleTransmission</type>
    <joint name="joint1">
      <hardwareInterface>EffortJointInterface</hardwareInterface>
    </joint>
    <actuator name="motor1">
      <hardwareInterface>EffortJointInterface</hardwareInterface>
      <mechanicalReduction>1</mechanicalReduction>
    </actuator>
  </transmission>
  <transmission name="tran2">
    <type>transmission_interface/SimpleTransmission</type>
    <joint name="joint2">
      <hardwareInterface>EffortJointInterface</hardwareInterface>
    </joint>
    <actuator name="motor2">
      <hardwareInterface>EffortJointInterface</hardwareInterface>
      <mechanicalReduction>1</mechanicalReduction>
    </actuator>
  </transmission>
  <transmission name="tran3">
    <type>transmission_interface/SimpleTransmission</type>
    <joint name="nozzle_joint">
      <hardwareInterface>EffortJointInterface</hardwareInterface>
    </joint>
    <actuator name="motor3">
      <hardwareInterface>EffortJointInterface</hardwareInterface>
      <mechanicalReduction>1</mechanicalReduction>
    </actuator>
  </transmission>

</robot>